<?xml version="1.0"?>
<!-- ##############################################################################-->
<!--              URDF DESCRIPTION OF THE DIFFERENTIAL DRIVE ROBOT                 -->
<!-- ##############################################################################-->

<robot name="differential_drive_robot" xmlns:xacro="http://www.ros.org/wiki/xacro">

    <!-- ########################## Geometry and Constants ########################-->
    <!-- ##########################################################################-->

                                    <!-- Pi constant -->
    <xacro:property name="pi_const" value="3.14159265"/>

                                    <!-- chasis -->
    <xacro:property name="a" value="1" />                               <!-- length, along x axis-->
    <xacro:property name="b" value="0.3" />                             <!-- height, alomg z axis -->
    <xacro:property name="c" value="0.6"/>                              <!-- width, along y axis -->
    <xacro:property name="d1" value="2710.0"/>                          <!--density-->
    <xacro:property name="m1" value="${d1*a*b*c}"/>                     <!--mass -->
    <xacro:property name="Ix_chassis" value="${(1/12)*m1*(b*b+c*c)}"/>  <!-- moment of inertia along x axis-->
    <xacro:property name="Iy_chassis" value="${(1/12)*m1*(a*a+b*b)}"/>  <!-- moment of inertia along y axis-->
    <xacro:property name="Iz_chassis" value="${(1/12)*m1*(a*a+c*c)}"/>  <!-- moment of inertia along z axis-->

                                <!-- wheel (decsribed as cylinder)-->
    <xacro:property name="r2" value="0.15"/>                            <!-- Wheel radius --> 
    <xacro:property name="w" value="0.1"/>                              <!-- Wheel width --> 
    <xacro:property name="d2" value="2710.0"/>                          <!--density-->
    <xacro:property name="m2" value="${d2*pi_const*r2*r2*w}"/>          <!--mass -->
    <xacro:property name="I_wheel" value="${(1/12)*m2*(3*r2*r2+w*w)}"/> <!-- moment of inertia along x,y axis. Ix=Iy so denoted by I-->
    <xacro:property name="Iz_wheel" value="${0.5*m2*r2*r2}"/>           <!-- moment of inertia along z axis-->


                            <!-- caster wheel-->
    <xacro:property name="r3" value="0.15"/>                            <!--caster wheel radius --> 
    <xacro:property name="d3" value="2710.0"/>                          <!--density-->
    <xacro:property name="m3" value="${d3*(4/3)*pi_const*r3*r3*r3}"/>   <!--mass -->
    <xacro:property name="I_caster" value="${(2/5)*m3*r3*r3}"/>         <!-- moment of inertia along x,y,z axis,Ix=Iy=Iz for sphere-->

                        <!-- other useful dimensions -->
    <xacro:property name="s1" value="${b/2+r2}"/>                       <!--  -->
    <xacro:property name="s2" value="${2*r2}"/>                         <!--  -->
    <xacro:property name="s3" value="${2*r2}"/>                         <!--  -->
    <xacro:property name="s4" value="${c/2+w/2}"/>                      <!--  -->

    <!--######################### inertial properties ################################-->
    <!-- this section describes the mass, inertia, postion of link frame(coordinates system 
    at the centre of mass of the link) with reference to reference frame. all as macro-->
    <!--###############################################################################-->

    <xacro:macro name="inertia_chassis">
        <inertial>
            <origin rpy="0 0 0" xyz="0 0 ${s1}" />
            <mass value="${m1}"/>
            <inertia ixx="${Ix_chassis}" iyy="${Iy_chassis}" izz="${Iz_chassis}" ixy="0" ixz="0" iyz="0"/> <!-- tensor of inertia-->
         </inertial>
    </xacro:macro>

    <xacro:macro name="inertia_wheel">
        <inertial>
            <origin rpy="1.570795 0 0" xyz="0 0 0" />
            <mass value="${m2}"/>
            <inertia ixx="${I_wheel}" iyy="${I_wheel}" izz="${Iz_wheel}" ixy="0" ixz="0" iyz="0"/> <!-- tensor of inertia-->
         </inertial>
    </xacro:macro>

     <xacro:macro name="inertia_caster">
        <inertial>
            <origin rpy="0 0 0" xyz="0 0 0" />
            <mass value="${m3}"/>
            <inertia ixx="${I_caster}" iyy="${I_caster}" izz="${I_caster}" ixy="0" ixz="0" iyz="0"/> <!-- tensor of inertia-->
         </inertial>
    </xacro:macro>

    <!-- ########################## file include ###################################-->
    <!--           this section is for linking useful files                          -->
    <!-- ############################################################################-->

    <xacro:include filename="$(find car)/urdf/two_wheel_car.gazebo"/>


    <!-- ########################### links #########################################-->
    <!--            this section defines all links in the robot                     -->
    <!-- ###########################################################################-->

    <link name="base_footprint"/> <!-- this is a fictious link,for referencing chassic link-->
    
    <link name="chassis">
        <visual>
            <geometry>
                <box size= "${a} ${c} ${b}" />
            </geometry>
            <origin rpy="0 0 0" xyz="0 0 ${s1}"/> <!-- displacement and orientation of link frame with respect to reference frame-->
        </visual>
        <collision>
            <geometry>
                <box size= "${a} ${c} ${b}" />
            </geometry>
            <origin rpy="0 0 0" xyz="0 0 ${s1}"/>
        </collision>
        <xacro:inertia_chassis/>
    </link>
    
    <link name="right_wheel">
        <visual>
            <geometry>
                <cylinder length="${w}" radius="${r2}"/>
            </geometry>
            <origin rpy="1.570795 0 0" xyz="0 0 0"/>
        </visual>
        <collision>
            <geometry>
                <cylinder length="${w}" radius="${r2}"/>
            </geometry>
            <origin rpy="1.570795 0 0" xyz="0 0 0"/>
        </collision>
        <xacro:inertia_wheel/>
    </link>

    <link name="left_wheel">
         <visual>
            <geometry>
                <cylinder length="${w}" radius="${r2}"/>
            </geometry>
            <origin rpy="1.570795 0 0" xyz="0 0 0"/>
        </visual>
        <collision>
            <geometry>
                <cylinder length="${w}" radius="${r2}"/>
            </geometry>
            <origin rpy="1.570795 0 0" xyz="0 0 0"/>
        </collision>
        <xacro:inertia_wheel/>
    </link>

    <link name="caster_wheel">
        <visual>
            <geometry>
                <sphere radius="${r3}"/>
            </geometry>
            <origin rpy="0 0 0" xyz="0 0 0"/>
        </visual>
        <collision>
            <geometry>
                <sphere radius="${r3}"/>
            </geometry>
            <origin rpy="0 0 0" xyz="0 0 0"/>
        </collision>
        <xacro:inertia_caster/>
    </link>


    <!-- ########################### joints #########################################-->
    <!--        this section defines all joints in the robot                         -->
    <!-- ############################################################################-->
    
    <joint name="body_link_joint" type="fixed">
        <parent link="base_footprint"/>
        <child link="chassis"/>
    </joint>

    <joint name="right_wheel_joint" type="continuous">
        <parent link="chassis"/>
        <child link="right_wheel"/>
        <origin rpy="0 0 0" xyz="${-s2} ${-s4} ${r2}"/>
        <axis xyz="0 1 0"/>
        <limit effort="50000" velocity="10"/>
        <dynamics damping="1.0" friction="1.0"/>
    </joint>

    <joint name="left_wheel_joint" type="continuous">
        <parent link="chassis"/>
        <child link="left_wheel"/>
        <origin rpy="0 0 0" xyz="${-s2} ${s4} ${r2}"/>
        <axis xyz="0 1 0"/>
        <limit effort="50000" velocity="10"/>
        <dynamics damping="1.0" friction="1.0"/>
    </joint>

    <!-- caster wheel joint is fixed now.in practical case it is different-->
    <joint name="caster_wheel_joint" type="fixed">
        <parent link="chassis"/>
        <child link="caster_wheel"/>
        <origin rpy="0 0 0" xyz="${s3} 0 ${r3}"/>
    </joint> 

</robot>